
## TensorFlow의 설치및 기본적인 operations (new)

### TensorFlow란
- Data flow graphs를 사용해서 numerical 계산을 할 수 있는 라이브러리
- Python으로 구현 가능

<br/>

### Data Flow Graph란
- 하나의 노드는 연산자로 구성
- 간선은 데이터 배열(tensors)로 구성

<br/>

### TensorFlow 설치하기
- Linux, Max OSX, Windows
    + (sudo -H) pip install --upgrade tensorflow
    + (sudo -H) pip install --upgrade tensorflow-gpu
    
<br/>

### TensorFlow 설치 및 버전 확인하기


```python
import tensorflow as tf

tf.__version__
```


    ---------------------------------------------------------------------------

    ImportError                               Traceback (most recent call last)

    /anaconda3/lib/python3.6/site-packages/tensorflow/python/pywrap_tensorflow.py in <module>()
         40     sys.setdlopenflags(_default_dlopen_flags | ctypes.RTLD_GLOBAL)
    ---> 41   from tensorflow.python.pywrap_tensorflow_internal import *
         42   from tensorflow.python.pywrap_tensorflow_internal import __version__


    /anaconda3/lib/python3.6/site-packages/tensorflow/python/pywrap_tensorflow_internal.py in <module>()
         27             return _mod
    ---> 28     _pywrap_tensorflow_internal = swig_import_helper()
         29     del swig_import_helper


    /anaconda3/lib/python3.6/site-packages/tensorflow/python/pywrap_tensorflow_internal.py in swig_import_helper()
         23             try:
    ---> 24                 _mod = imp.load_module('_pywrap_tensorflow_internal', fp, pathname, description)
         25             finally:


    /anaconda3/lib/python3.6/imp.py in load_module(name, file, filename, details)
        242         else:
    --> 243             return load_dynamic(name, filename, file)
        244     elif type_ == PKG_DIRECTORY:


    /anaconda3/lib/python3.6/imp.py in load_dynamic(name, path, file)
        342             name=name, loader=loader, origin=path)
    --> 343         return _load(spec)
        344 


    ImportError: dlopen(/anaconda3/lib/python3.6/site-packages/tensorflow/python/_pywrap_tensorflow_internal.so, 10): Library not loaded: @rpath/libcublas.8.0.dylib
      Referenced from: /anaconda3/lib/python3.6/site-packages/tensorflow/python/_pywrap_tensorflow_internal.so
      Reason: image not found

    
    During handling of the above exception, another exception occurred:


    ImportError                               Traceback (most recent call last)

    <ipython-input-1-69e5d056d1fc> in <module>()
    ----> 1 import tensorflow as tf
          2 
          3 tf.__version__


    /anaconda3/lib/python3.6/site-packages/tensorflow/__init__.py in <module>()
         22 
         23 # pylint: disable=wildcard-import
    ---> 24 from tensorflow.python import *
         25 # pylint: enable=wildcard-import
         26 


    /anaconda3/lib/python3.6/site-packages/tensorflow/python/__init__.py in <module>()
         49 import numpy as np
         50 
    ---> 51 from tensorflow.python import pywrap_tensorflow
         52 
         53 # Protocol buffers


    /anaconda3/lib/python3.6/site-packages/tensorflow/python/pywrap_tensorflow.py in <module>()
         50 for some common reasons and solutions.  Include the entire stack trace
         51 above this error message when asking for help.""" % traceback.format_exc()
    ---> 52   raise ImportError(msg)
         53 
         54 # pylint: enable=wildcard-import,g-import-not-at-top,unused-import,line-too-long


    ImportError: Traceback (most recent call last):
      File "/anaconda3/lib/python3.6/site-packages/tensorflow/python/pywrap_tensorflow.py", line 41, in <module>
        from tensorflow.python.pywrap_tensorflow_internal import *
      File "/anaconda3/lib/python3.6/site-packages/tensorflow/python/pywrap_tensorflow_internal.py", line 28, in <module>
        _pywrap_tensorflow_internal = swig_import_helper()
      File "/anaconda3/lib/python3.6/site-packages/tensorflow/python/pywrap_tensorflow_internal.py", line 24, in swig_import_helper
        _mod = imp.load_module('_pywrap_tensorflow_internal', fp, pathname, description)
      File "/anaconda3/lib/python3.6/imp.py", line 243, in load_module
        return load_dynamic(name, filename, file)
      File "/anaconda3/lib/python3.6/imp.py", line 343, in load_dynamic
        return _load(spec)
    ImportError: dlopen(/anaconda3/lib/python3.6/site-packages/tensorflow/python/_pywrap_tensorflow_internal.so, 10): Library not loaded: @rpath/libcublas.8.0.dylib
      Referenced from: /anaconda3/lib/python3.6/site-packages/tensorflow/python/_pywrap_tensorflow_internal.so
      Reason: image not found
    
    
    Failed to load the native TensorFlow runtime.
    
    See https://www.tensorflow.org/install/install_sources#common_installation_problems
    
    for some common reasons and solutions.  Include the entire stack trace
    above this error message when asking for help.

